2020-04-23 02:19:05.352327    UnableToWorkException:
 Traceback (most recent call last):
  File "/home/user/git/modules/exceptions/app.py", line 36, in <module>
    main()
  File "/home/user/git/modules/exceptions/app.py", line 30, in main
    print(c_3.work())                   #ошибка
  File "/home/user/git/modules/exceptions/workers/candidate.py", line 13, in work
    raise UnableToWorkException('I’m not hired yet, lol.')
workers.candidate.UnableToWorkException: I’m not hired yet, lol.


2020-04-23 02:23:50.031946    UnableToWorkException:
 Traceback (most recent call last):
  File "/home/user/git/modules/exceptions/app.py", line 36, in <module>
    main()
  File "/home/user/git/modules/exceptions/app.py", line 30, in main
    print(c_3.work())                   #ошибка
  File "/home/user/git/modules/exceptions/workers/candidate.py", line 13, in work
    raise UnableToWorkException('I’m not hired yet, lol.')
workers.candidate.UnableToWorkException: I’m not hired yet, lol.


2020-04-23 02:25:09.480489    UnableToWorkException:
 Traceback (most recent call last):
  File "/home/user/git/modules/exceptions/app.py", line 36, in <module>
    main()
  File "/home/user/git/modules/exceptions/app.py", line 30, in main
    print(c_3.work())                   #ошибка
  File "/home/user/git/modules/exceptions/workers/candidate.py", line 13, in work
    raise UnableToWorkException('I’m not hired yet, lol.')
workers.candidate.UnableToWorkException: I’m not hired yet, lol.


2020-04-23 02:26:42.765516    UnableToWorkException:
 Traceback (most recent call last):
  File "/home/user/git/modules/exceptions/app.py", line 36, in <module>
    main()
  File "/home/user/git/modules/exceptions/app.py", line 30, in main
    print(c_3.work())                   #ошибка
  File "/home/user/git/modules/exceptions/workers/candidate.py", line 13, in work
    raise UnableToWorkException('I’m not hired yet, lol.')
workers.candidate.UnableToWorkException: I’m not hired yet, lol.


2020-04-23 02:27:03.651004    UnableToWorkException:
 Traceback (most recent call last):
  File "/home/user/git/modules/exceptions/app.py", line 36, in <module>
    main()
  File "/home/user/git/modules/exceptions/app.py", line 30, in main
    print(c_3.work())                   #ошибка
  File "/home/user/git/modules/exceptions/workers/candidate.py", line 13, in work
    raise UnableToWorkException('I’m not hired yet, lol.')
workers.candidate.UnableToWorkException: I’m not hired yet, lol.


2020-04-23 02:28:32.442528    UnableToWorkException:
 Traceback (most recent call last):
  File "/home/user/git/modules/exceptions/app.py", line 36, in <module>
    main()
  File "/home/user/git/modules/exceptions/app.py", line 30, in main
    print(c_3.work())                   #ошибка
  File "/home/user/git/modules/exceptions/workers/candidate.py", line 13, in work
    raise UnableToWorkException
workers.candidate.UnableToWorkException


2020-04-23 02:29:00.521950    NameError:
 Traceback (most recent call last):
  File "/home/user/git/modules/exceptions/app.py", line 36, in <module>
    main()
  File "/home/user/git/modules/exceptions/app.py", line 27, in main
    print(p_3.check_salary(100))        #ошибка
NameError: name 'p_3' is not defined


2020-04-23 02:30:03.908735    UnableToWorkException:
 Traceback (most recent call last):
  File "/home/user/git/modules/exceptions/app.py", line 36, in <module>
    main()
  File "/home/user/git/modules/exceptions/app.py", line 30, in main
    print(c_3.work())                   #ошибка
  File "/home/user/git/modules/exceptions/workers/candidate.py", line 13, in work
    raise UnableToWorkException
workers.candidate.UnableToWorkException


2020-04-23 02:30:18.763601    UnableToWorkException:
 Traceback (most recent call last):
  File "/home/user/git/modules/exceptions/app.py", line 36, in <module>
    main()
  File "/home/user/git/modules/exceptions/app.py", line 30, in main
    print(c_3.work())                   #ошибка
  File "/home/user/git/modules/exceptions/workers/candidate.py", line 13, in work
    raise UnableToWorkException
workers.candidate.UnableToWorkException


2020-04-23 02:30:56.059375    UnableToWorkException:
 Traceback (most recent call last):
  File "/home/user/git/modules/exceptions/app.py", line 36, in <module>
    main()
  File "/home/user/git/modules/exceptions/app.py", line 30, in main
    print(c_3.work())                   #ошибка
  File "/home/user/git/modules/exceptions/workers/candidate.py", line 13, in work
    raise UnableToWorkException('I’m not hired yet, lol.')
workers.candidate.UnableToWorkException: I’m not hired yet, lol.


2020-04-23 02:39:23.075995    UnableToWorkException:
 Traceback (most recent call last):
  File "/home/user/git/modules/exceptions/app.py", line 36, in <module>
    main()
  File "/home/user/git/modules/exceptions/app.py", line 30, in main
    print(c_3.work())                   #ошибка
  File "/home/user/git/modules/exceptions/workers/candidate.py", line 13, in work
    raise UnableToWorkException
workers.candidate.UnableToWorkException


2020-04-23 02:39:59.156165    UnableToWorkException:
 Traceback (most recent call last):
  File "/home/user/git/modules/exceptions/app.py", line 36, in <module>
    main()
  File "/home/user/git/modules/exceptions/app.py", line 30, in main
    print(c_3.work())                   #ошибка
  File "/home/user/git/modules/exceptions/workers/candidate.py", line 14, in work
    raise UnableToWorkException
workers.candidate.UnableToWorkException


2020-04-23 19:42:00.680404    AttributeError:
 Traceback (most recent call last):
  File "/home/user/git/modules/exceptions/app.py", line 40, in <module>
    main()
  File "/home/user/git/modules/exceptions/app.py", line 26, in main
    c_1.work()
AttributeError: 'Candidate' object has no attribute 'work'


2020-04-23 19:49:09.546364    NameError:
 Traceback (most recent call last):
  File "/home/user/git/modules/exceptions/app.py", line 27, in main
    c_1.work()
  File "/home/user/git/modules/exceptions/workers/candidate.py", line 13, in work
    raise UnableToWorkException('I’m not hired yet, lol.')
workers.candidate.UnableToWorkException: I’m not hired yet, lol.

During handling of the above exception, another exception occurred:

Traceback (most recent call last):
  File "/home/user/git/modules/exceptions/app.py", line 43, in <module>
    main()
  File "/home/user/git/modules/exceptions/app.py", line 28, in main
    except UnableToWorkException:
NameError: name 'UnableToWorkException' is not defined


